Workbook

Sheet 表紙
A1: RFP添付資料3_要求機能一覧
B5: 提案会社名 | D5: 株式会社システムインテグレータ | J5: ←社名を記入ください
A8: 記入要綱
B9: 貴社記入欄「実現方法」に「標準」「アドオン・カスタマイズ」「不可」のいずれかを回答ください。
B10: 「回答詳細」欄に回答内容を記載ください。
B11: 「実現方法」で「アドオン・カスタマイズ」を選択した場合、「アドオン・カスタマイズ概算費用」を記載ください。
B12: DFDに沿って記載しているため、同じ要求機能が複数行に記載されています。その場合は、「連番〇〇〇と同じ」
B13: と回答詳細に記載下さい。「実現方法」は設定ください。
B15: 全て、シートに直接入力をお願いします。
B16: 備考欄に質問を記入して送り返すことはしないでください。
B17: 質問はまとめて、別途質問シートにて提出を願いします。
B18: 記入された内容について、詳細かつ明瞭に記述してください。
B19: 会社名を必ず入力してください。
B20: 「必須/OP」欄について、「必須」は必須機能、「OP」はオプション機能を意味します。

Sheet 要求機能一覧
A3: 当社記入欄 | I3: 貴社記入欄（実現方法）
A4: 連番 | B4: Lv1 | C4: Lv2 | D4: 処理ID | E4: 処理名 | F4: システム要件 | G4: 必須 /OP | H4: 帳票 | I4: 実現方法 | J4: 回答詳細 | K4: アドオン・カスタマイズ 概算費用（円） | L4: メモ | M4: Aド標準 B運用変更 C運用負荷大 | N4: 北勝/玉置 | O4: 機能名
A5: 1 | B5: 1.購買 | C5: 1.所要量計算 | D5: 1.1 | E5: 生産計画入力 | F5: 月次生産計画を入力する | G5: 必須 | I5: 標準 | J5: 月次、週次、日次単位で生産計画を入力する機能を具備しております。 | K5: - | M5: A | N5: 北勝
A6: 2 | B6: 1.購買 | C6: 1.所要量計算 | D6: 1.2 | E6: 所要量計算 | F6: 入力された生産計画に基づき、在庫を踏まえ生産に必要な半製品・部材・資材の手配数を計算する 処理が軽量で、日中でも十分活用できるパフォーマンスが出ること 所要量計算処理において、月次処理へ影響しないシミュレーションができること 以下の要件も満たすこと ・確定期間（Time Fence）の設定 ・在庫の再引当（引当変更）機能 ・需要に対する優先順位付け機能 または、（運用）定期的な引当の見直し ・MRPの柔軟な実行制御 資材所要量計画（MRP）を必要に応じて任意タイミングで実行可能とする ・月次処理との共存運用 締処理・伝票管理とMRP実行を相互に干渉させないスケジューリング機能を有するもの ・計画と手配の即時連携 生産計画入力後、即座に資材展開・所要確認が行われること ・仮計画ベースでのMRPシミュレーション機能の導入 なお、先行手配が必要な品目（例えば、半導体）は、通常品とは異なることが区分けできる区分を品目マスタに設定でき、先行手配のための所要量計算ができること ・子部品からの逆展開 子部品の現在庫から親品目（最終製品）がいくら製造できるか逆展開で所要量計算できること | G6: 必須 | I6: 標準 | J6: 確定期間の設定、在庫の再引当機能、 需要に対する優先順位付け機能を具備しております。 また、定期的な引当見直しは特定条件下で実行が可能です。 MRPは任意のタイミングで、月次処理と相互に干渉なく実行することができます。 生産計画入力は即時反映され、資材展開・所要量確認ができます。 仮計画ベースでのMRPシミュレーション、先行手配品の所要量計算にも対応しております。 子部品からの逆展開について、BOM展開と在庫情報の組み合わせによる間接的な確認が可能です。 | K6: - | L6: 1JW（拡張ATP）追加ライセンス | M6: B | N6: 北勝
A7: 3 | B7: 1.購買 | C7: 2.発注検討 | D7: 2.1 | E7: 発注検討書出力 | F7: 発注の要否、および、発注日、発注数量を検討するための帳票を出力する | G7: 必須 | H7: 〇 | I7: 標準 | J7: 従来の紙ベースの帳票に代わり、リアルタイムの在庫・所要状況を可視化し、発注の意思決定を支援する対話型の機能が標準で提供されています。 また、各アプリには、表示されているリストをそのままExcel形式でダウンロードする機能が標準で備わっています。 | K7: - | M7: B | N7: 北勝
A8: 4 | B8: 1.購買 | C8: 2.発注検討 | D8: 2.2 | E8: 発注検討・承認 | F8: 発注検討結果を承認する | G8: 必須 | I8: 標準 | J8: MRPや手動で作成された購買依頼（PR）に対し、ワークフロー機能を用いた承認プロセスを標準で備えています。 | K8: - | M8: A | N8: 北勝
A9: 5 | B9: 1.購買 | C9: 2.発注検討 | D9: 2.3 | E9: 品目別在庫照会 | F9: 品目別の在庫状況を画面に出力する なお、現時点の在庫情報の照会だけでなく、 PSI（生産（Production）、販売（Sales）、在庫（Inventory））の推移を、将来の在庫推移（入荷予定・生産予定・出荷予定）を踏まえて、在庫推移が照会できること | G9: 必須 | I9: 標準 | J9: 品目別の在庫照会機能を具備しております。 生産・販売・在庫で個別の推移確認が可能です。 複数のアプリケーションを効果的に組み合わせた運用により、入荷予定・生産予定・出荷予定を踏まえたPSI推移の照会が可能となり、実用的なレベルでのPSI推移管理が実現できます。 | K9: - | M9: B | N9: 北勝
A10: 6 | B10: 1.購買 | C10: 3.発注 | D10: 3.1 | E10: 発注書発行 | F10: 発注書及び当社指定納品書も発行する （外貨が扱えること） | G10: 必須 | H10: 〇 | I10: アドオン・カスタマイズ | J10: 標準帳票での運用ができないと判断された場合にはアドオン開発が必要です。 | K10: 800000 | N10: 北勝 | O10: 指定納品書
A11: 7 | B11: 1.購買 | C11: 3.発注 | D11: 3.2 | E11: 楽々明細連携 | F11: 基幹システムから発行された書面を所定の取引先へ送付するために楽々明細へ送信する | G11: 必須 | I11: アドオン・カスタマイズ | J11: 外部サービスへ連携するためのアドオン開発が必要です。 添付資料9の「社内・社外間IF一覧」に記載されている仕入先向けの注文書および納品書、得意先向けの作業報告書および納品書を対象に当要件でのお見積とします。 | K11: 7200000 | N11: 北勝 | O11: 注文書楽楽連携 仕入先納品書楽楽連携 作業報告書楽楽連携 得意先納品書楽楽連携
A12: 8 | B12: 1.購買 | C12: 3.発注 | D12: 3.3 | E12: 納期回答受領 | F12: 納期回答をデータとして受信する 発注数が多い仕入先には一部機能を公開し、直接納期回答を入力してもらう または、対応できる仕入先においては、EDIによるデータ連携も可能とする | G12: 必須 | I12: アドオン・カスタマイズ | J12: SAPの標準機能には、特定の仕入先向けに納期回答用の専用画面を直接公開する機能および納期回答データを受信する機能は具備されていないため、アドオン開発が必要です。 EDI/データ連携：システム間連携が可能な仕入先とは、SAPの標準APIを用いて納期回答を直接受信し、購買発注データへ自動反映させることを想定しています。 ポータル画面に代わる運用：特定の仕入先向けに専用画面を構築・公開する手法は、開発・維持コストの観点から推奨いたしません。代替として、SAPの発注情報をメールやデータ（Excel等）で送付し、仕入先からの回答をAsteriaを活用してシステムへ取り込む運用を想定しています。 | K12: 3000000 | L12: SAP Business Network | N12: 北勝 | O12: 納期回答データEDI取込 納期回答データファイル取込
A13: 9 | B13: 1.購買 | C13: 4.受入 | D13: 4.1 | E13: 入荷実績入力 | F13: 購買発注した部材・資材の入荷実績を入力する 今回導入する現場システム（HTT）と基幹システムがデータ連携できること 現場での受け払いに係る入力は、現場システム（ハンディターミナル）を用いて行う そのため、現品には、品目を特定するためのバーコードが貼り付けられ、各種指示や伝票には、指示を特定するためにバーコードが印刷されていること 基幹システムと現場システムとは、人を介さず、自動でデータ連携できること | G13: 必須 | I13: アドオン・カスタマイズ | J13: ハンディターミナルによる仕入入庫データを取り込む機能のアドオン開発が必要です。 | K13: 1500000 | L13: ラベル印刷(F1563) Scope Item：3HQ | N13: 北勝 | O13: ハンディ仕入入庫データ取込
A14: 10 | B14: 1.購買 | C14: 4.受入 | D14: 4.1a | E14: 納入予定データ受信 | F14: 仕入先よりEDI経由で納入予定データを受信する | G14: 任意 | I14: アドオン・カスタマイズ | J14: EDI経由でデータを取り込むためのアドオン開発が必要です。 | K14: 1500000 | N14: 北勝 | O14: 納入予定データEDI取込
A15: 11 | B15: 1.購買 | C15: 4.受入 | D15: 4.2 | E15: 仕入入力 | F15: 仕入処理にて、仕入仕訳が自動で発生すること （5.4.1参照） （外貨が扱えること） よって、受入処理（倉庫側）と仕入処理（購買または経理） ※支払通知書で運用している。（請求書照合は行っていない） 課税・非課税は、仕入先単位での設定 （外貨が扱えること） | G15: 必須 | I15: 標準 | J15: 以下の機能を具備しております。 ・受入処理（入庫）および仕入処理（請求書照合または自動振替）の会計仕訳のリアルタイム自動生成 ・請求書照合不要の「支払通知書」運用 ・仕入先ごとの柔軟な税・外貨対応 | K15: - | M15: A | N15: 北勝
A16: 12 | B16: 1.購買 | C16: 5.支給指示 | D16: 5.1 | E16: 支給予定照会 | F16: 外注加工先への支給予定を画面に出力する なお、有償支給・無償支給において、以下の対応ができること 無償支給： MRPにより支給数が算出され、支給指示書としてまとめる （複数の支給先があろうと、必要なときに必要な数量は算出される） 有償支給： 当社主導）支給数は上記の通り算出され、支給指示書を発行する_x000B_ 先方手動）支給先の支給依頼（発注）に基づいて支給する | G16: 必須 | I16: 標準 | J16: 無償支給・有償支給ともに標準機能を具備しております。 MRP連動の支給数算出、支給指示、有償支給に対する債権相殺まで対応しております。 | K16: - | M16: A | N16: 北勝
A17: 13 | B17: 1.購買 | C17: 5.支給指示 | D17: 5.2 | E17: 支給指示書発行 | F17: 外注加工先への支給指示書を出力する 外注加工手配および支給品の手配も、所要量計算の対象とする 人手による作業を軽減するために、個装単位等、ロットまとめ方式など、所要量計算で対応できること ・外注加工の手配も所要量計算の対象とし、所要量計算の結果、どの外注加工先に、どの品目をいつまでに、いくつ生産しなければならないかが明確になります。 ・支給数も所要量計算の対象とし、その外注加工手配に基づいて、所要量計算後、部品数とその場合のリール数を算出されます。なお、リールについては、個装単位を設けることで、１リールあたりの部品点数が予め登録されているため、部品数に基づいてリール数が算出されます | G17: 必須 | H17: 〇 | I17: 標準 | J17: 支給指示書発行機能、およびMRP実行による外注加工と支給品の管理機能、基本的な単位換算機能を具備しております。 | K17: - | M17: A | N17: 北勝
A18: 14 | B18: 1.購買 | C18: 6.支給 | D18: 6.1 | E18: 支給実績入力 | F18: 外注加工先への支給実績を入力する 外注加工先への材料直送実績の入力について、以下の選択肢が選択できること なお、５は、取引先様にてご協力いただけない場合の対応方法 １．仕入先（材料業者）に支給実績を入力してもらう（入力画面の提供） ２．仕入先（加工業者）に受領実績を入力してもらう（入力画面の提供） ３．仕入先（材料業者）から支給実績データを提供いただく（EDI） ４．仕入先（加工業者）から受領実績データを提供いただく（EDI） ５．当社にて一括登録 | G18: 必須 | I18: アドオン・カスタマイズ | J18: SAPの標準機能には、特定の取引先向けに専用画面を直接公開する機能は具備されていないため、アドオン開発が必要です。 EDI/データ連携：システム間連携が可能な取引先とは、SAPの標準APIを用いて実績情報を直接受信し、SAP上で実績計上することを想定しています。 ポータル画面に代わる運用：特定の取引先向けに専用画面を構築・公開する手法は、開発・維持コストの観点から推奨いたしません。代替として、SAPの発注情報をメールやデータ（Excel等）で送付し、取引先からの実績情報をAsteriaを活用してシステムへ取り込む運用を想定しています。 | K18: 3000000 | N18: 北勝 | O18: 支給実績データEDI取込 支給実績データファイル取込
A19: 15 | B19: 1.購買 | C19: 6.支給 | D19: 6.2 | E19: 移動指示書発行 | F19: 社内の在庫移動の指示書を発行する なお、計画外の在庫移動（数量変更）は、承認を得るように、ワークフローが実装できること | G19: 必須 | H19: 〇 | I19: 標準 | J19: 在庫転送オーダーに基づく在庫移動指示書の発行機能および 計画外の数量変更や移動に対する承認機能を具備しております。 | K19: - | M19: A | N19: 北勝
A20: 16 | B20: 1.購買 | C20: 6.支給 | D20: 6.3 | E20: 移動実績入力 | F20: 社内の在庫移動結果を入力する | G20: 必須 | I20: 標準 | J20: プラント間移動、保管場所間移動、在庫ステータス変更などの実績入力を行う機能を具備しております。 | K20: - | M20: A | N20: 北勝
A21: 17 | B21: 2.製造 | C21: 1.年間計画 | D21: 1.1 | E21: 年間生産計画立案 | F21: 年間生産計画を立案する 年次計画の策定においては、販売・製造する製品の仕様が定まっていない場合があるため、製品カテゴリ単位で、代表品目を設定し、その代表品目（カテゴリ品目）を用いて立案することで対応できること 生産計画の立案において、備忘情報として、改造情報（from-to）や数量変更情報等の定性情報がメモできること 海外子会社との生産計画の共有において、現行システム（出荷システム）を用いて行っている。引き続き、当該システムを利用するため、自動でデータ連携が行えること | G21: 必須 | I21: アドオン・カスタマイズ | J21: 計画用品目や製品グループ機能により、仕様未定段階でのカテゴリ単位の立案に対応します。 計画展開後の各トランザクションにテキストを保持する機能を具備しております。 現行システム（出荷システム）との自動データ連携については、アドオン開発が必要です。 | K21: 1500000 | L21: 生産計画管理にテキストあり。 | N21: 北勝 | O21: 生産計画データ送信
A22: 18 | B22: 2.製造 | C22: 2.生産計画（月次） | D22: 2.1 | E22: 年間生産計画修正 | F22: 立案された年間生産計画を修正する 生産計画の立案において、備忘情報として、改造情報（from-to）や数量変更情報等の定性情報がメモできること | G22: 必須 | I22: 標準 | J22: 計画独立所要量（PIR）の修正・更新に対応しており、即座に後続のMRPへ反映可能です。 計画展開後の各トランザクションにテキストを保持する機能を具備しております。 | K22: - | L22: 生産計画管理にテキストあり。 | M22: A | N22: 北勝
A23: 19 | B23: 2.製造 | C23: 2.生産計画（月次） | D23: 2.2 | E23: 生産実績反映 | F23: 月次生産計画を立案するために、生産実績を反映する | G23: 必須 | I23: 標準 | J23: 実績を考慮した計画立案を行う独立需要計画（PIR）とMRP機能を具備しております。 | K23: - | M23: A | N23: 北勝
A24: 20 | B24: 2.製造 | C24: 2.生産計画（月次） | D24: 2.3 | E24: 月次生産計画立案 | F24: 月次生産計画を立案する | G24: 必須 | I24: 標準 | J24: 月次、週次、日次単位で生産計画を入力する機能を具備しております。 | K24: - | M24: A | N24: 北勝
A25: 21 | B25: 2.製造 | C25: 3.所要量計算 | D25: 3.1 | E25: 生産計画入力 | F25: 1.1.1と同じ | G25: 必須 | I25: 標準 | J25: 連番1と同じ | K25: - | M25: A | N25: 北勝
A26: 22 | B26: 2.製造 | C26: 3.所要量計算 | D26: 3.2 | E26: 所要量計算 | F26: 1.1.2と同じ | G26: 必須 | I26: 標準 | J26: 連番2と同じ | K26: - | M26: B | N26: 北勝
A27: 23 | B27: 2.製造 | C27: 3.所要量計算 | D27: 3.2a | E27: 能力計算 | F27: 所要量計算処理後、リソース（設備・人）の能力を考慮した能力計画ができること | G27: 必須 | I27: 標準 | J27: 単純な負荷確認から、ガントチャートを用いたドラッグ＆ドロップによるリスケジュール、さらには高度な自動スケジューリングまで、要件の複雑さに応じた標準機能が具備しております。 | K27: - | M27: A | N27: 北勝
A28: 24 | B28: 2.製造 | C28: 3.所要量計算 | D28: 3.3 | E28: 注文書発行 | F28: 発注書及び当社指定納品書も発行する | G28: 必須 | H28: 〇 | I28: アドオン・カスタマイズ | J28: 連番6と同じ | K28: - | N28: 北勝 | O28: -
A29: 25 | B29: 2.製造 | C29: 3.所要量計算 | D29: 3.4 | E29: 使用部品一覧表発行 | F29: 製造に必要な半製品・部材の使用一覧を出力する | G29: 必須 | H29: 〇 | I29: 標準 | J29: 製品を作るために必要な部材を多階層で一覧出力する機能を具備しております。 | K29: - | M29: A | N29: 北勝
A30: 26 | B30: 2.製造 | C30: 3.所要量計算 | D30: - | E30: 部品構成マスタ | F30: 部品構成表に代替品・同等品が登録でき、優先度、有効期限、在庫消化切り替えの基準にて、代替品・同等品への切り替えが行える機能が実装されていること 部品構成表の中に、代替品（同等品）の登録ができ、かつ、優先順位も設定できること。 また、後継品への切り替え時にも当該機能を用いることで、予め部品構成として登録することで、切替時の煩雑さの軽減を期待できる 現行の課題を解消するために、以下の要件が必要と考えます。 ・同等品グループを予め登録し、当該グループに登録している品目の優先度が設定でき、優先度に応じて調達が必要な品目が設定される ・同等品グループに登録されている品目の有効期限を設けることで、後継品の切り替え時期として利用できる ・後継品への切り替えにあたり、旧部材の在庫がなくなった時点で、後継品に切り替える | G30: 必須 | I30: 標準 | J30: 登録している品目の優先度を設定し、優先度に応じて調達が必要な品目を設定する機能を具備しております。 同等品の有効期限設定についてはBOMのバージョン管理を後継品切り替え時期としての利用に対応しています。 また旧部材の在庫がなくなった時点での後継品への自動切り替え機能を標準で具備しております。 | K30: - | M30: B | N30: 北勝
A31: 27 | B31: 2.製造 | C31: 4.製造指示 | D31: 4.1 | E31: 製造指示書発行 | F31: 製造指示書をは出力する | G31: 必須 | H31: 〇 | I31: 標準 | J31: 製造指図書の出力機能を具備しております。 | K31: - | M31: A | N31: 北勝
A32: 28 | B32: 2.製造 | C32: 5.ピッキング指示 | D32: 5.1 | E32: ピッキングリスト発行 | F32: ピッキングリストを出力する | G32: 必須 | H32: 〇 | I32: 標準 | J32: 出荷伝票、生産計画からのピッキングリストの出力機能を具備しております。 | K32: - | M32: A | N32: 北勝
A33: 29 | B33: 2.製造 | C33: 5.ピッキング指示 | D33: 5.2 | E33: 出庫実績入力 | F33: 社内の在庫移動（出庫）結果を入力する なお、在庫の受け払いにおいては、払出側・受入側に分けて、実績入力できること（2Step）。 但し、払出側・受入側の実績入力を求めず、実績入力することで、払出側・受入側が同時に実行される処理（1Step）も選択できること | G33: 必須 | I33: 標準 | J33: 業務要件や倉庫間の距離に応じて、1回の入力で移動を完了させる方式(Step1)か、払出と受入を分けて管理する方式(Step2)かを柔軟に選択可能です。 | K33: - | M33: A | N33: 北勝
A34: 30 | B34: 2.製造 | C34: 6.製造 | D34: 6.1 | E34: 製造実績入力 | F34: 製造実績（生産数、使用部品数）を入力する 製品の出来高を入力することで、構成品の消費量を理論値で引き落とすバックフラッシュ機能が具備されていること。 また、製造実績の入力においては、現場システム（ハンディターミナル等）が扱えること | G34: 必須 | I34: アドオン・カスタマイズ | J34: バックフラッシュ機能を具備しております。 ハンディターミナルによる生産入庫データを取り込む機能のアドオン開発が必要です。 | K34: 1500000 | N34: 北勝 | O34: ハンディ生産入庫データ取込
A35: 31 | B35: 3.在庫 | C35: 1.在庫照会 | D35: 1.1 | E35: 在庫照会 | F35: 1.2.3も含まれる。品目別注文残照会・引当状況照会も実現 | G35: 必須 | I35: 標準 | J35: 品目別注文残照会・引当状況照会を標準機能にて具備しております。 PSI推移の時系列分析機能については複数のアプリケーションを効果的に組み合わせた運用により、入荷予定・生産予定・出荷予定を踏まえたPSI推移の照会が可能となり、実用的なレベルで実現できます。 | K35: - | M35: B | N35: 北勝
A36: 32 | B36: 3.在庫 | C36: 2.出庫 | D36: 2.1 | E36: ピッキングリスト発行 | F36: 2.5.1と同じ | G36: 必須 | H36: 〇 | I36: 標準 | J36: 出荷伝票、生産計画からのピッキングリストの出力機能を具備しております。 | K36: - | M36: A | N36: 北勝
A37: 33 | B37: 3.在庫 | C37: 2.出庫 | D37: 2.4 | E37: 出庫実績入力 | F37: 2.5.2と同じ HTT（ハンディーターミナル）への出庫指示の送信 HTTによる出庫実績入力および基幹システムへの送信 | G37: 必須 | I37: アドオン・カスタマイズ | J37: ハンディターミナルへ出庫指示データを送信する機能のアドオン開発が必要です。 | K37: 1500000 | N37: 北勝 | O37: ハンディ出庫指示データ送信
A38: 34 | B38: 3.在庫 | C38: 2.出庫 | D38: 2.7 | E38: 移動実績入力 | F38: 1.6.3と同じ HTT（ハンディーターミナル）への移動指示の送信 HTTによる移動実績入力および基幹システムへの送信 | G38: 必須 | H38: 〇 | I38: アドオン・カスタマイズ | J38: ハンディターミナルによる移動実績データを取り込む機能のアドオン開発が必要です。 | K38: 1500000 | N38: 北勝 | O38: ハンディ移動実績データ取込
A39: 35 | B39: 3.在庫 | C39: 2.出庫 | D39: 2.8 | E39: 移動指示書発行 | F39: 1.6.2と同じ HTT（ハンディーターミナル）への移動指示の送信 | G39: 必須 | I39: アドオン・カスタマイズ | J39: ハンディターミナルへ移動指示データを送信する機能のアドオン開発が必要です。 | K39: 1500000 | N39: 北勝 | O39: ハンディ移動指示データ送信
A40: 36 | B40: 3.在庫 | C40: 2.出庫 | D40: 2.1 | E40: 支給指示書（リスト）発行 | F40: 1.5.2と同じ HTT（ハンディーターミナル）への支給指示の送信 | G40: 必須 | H40: 〇 | I40: アドオン・カスタマイズ | J40: ハンディターミナルへ支給指示データを送信する機能のアドオン開発が必要です。 | K40: 1500000 | N40: 北勝 | O40: ハンディ支給指示データ送信
A41: 37 | B41: 3.在庫 | C41: 2.出庫 | D41: 2.11 | E41: 支給実績入力 | F41: 1.5.3と同じ HTTによる支給（出庫）実績入力および基幹システムへの送信 （支給品の消費は、外注加工品の入荷時の処理） | G41: 必須 | I41: アドオン・カスタマイズ | J41: ハンディターミナルによる支給実績データを取り込む機能のアドオン開発が必要です。 | K41: 1500000 | N41: 北勝 | O41: ハンディ支給実績データ取込
A42: 38 | B42: 3.在庫 | C42: 3.入庫（入荷） | D42: 3.2 | E42: 入荷実績入力 | F42: 1.4.1と同じ HTT（ハンディーターミナル）への入荷予定の送信 HTTによる入荷実績入力および基幹システムへの送信 | G42: 必須 | I42: アドオン・カスタマイズ | J42: 連番9と同じ | K42: - | N42: 北勝 | O42: -
...

Sheet (参考)現行システム機能階層一覧
A1: No. | B1: 業務分類 | E1: 機能ID | F1: 機能名 | G1: 機能概要 | H1: 入力情報 | I1: 出力情報 | J1: 区分 | O1: 備考 | P1: 稼働状況 | Q1: step数 | R1: JCM | AB1: JCMシステムズ | AC1: メイホウ | AE1: スクショ採取
B2: 大分類 | C2: 中分類 | D2: 小分類 | J2: 画面 | K2: クエリ | L2: バッチ | M2: 帳表 | N2: CSV | R2: 情シス | S2: 経理 | T2: 営業 | U2: 人事 | V2: 総務 | W2: コンポーネント | X2: 生産技術 | Y2: 生産 | Z2: アジア営業 | AA2: 購買 | AD2: PG名 | AL2: JS機能 | AO2: 経理 | AS2: 人事
A3: 1 | B3: 販売システム | C3: マスター保守 | D3: ー | E3: SA0050 | F3: 与信マスター | J3: 〇 | Q3: =VLOOKUP(E3,sheet1!$B$2:$D$3209,3,FALSE) -> 1808 | R3: 〇 | S3: 〇 | T3: 〇 | U3: 〇 | V3: 〇 | AB3: 〇 | AC3: 〇 | AD3: =VLOOKUP(E3,sheet1!$B$2:$C$3209,2,FALSE) -> 与信マスターメンテナンス | AE3: 〇 | AF3: 01.与信マスター | AG3: SA0050 | AH3: =MID(AF3,4,100) -> 与信マスター | AO3: =TRIM(MIDB(AQ3,4,99)) -> 与信マスター | AP3: =TRIM(AR3) -> SA0050 | AQ3: 01.与信マスター | AR3: SA0050 | AS3: =TRIM(MID(AU3,4,99)) -> 与信マスター | AT3: =TRIM(AV3) -> SA0050 | AU3: 01.与信マスター | AV3: SA0050
A4: 2 | B4: 販売システム | C4: マスター保守 | D4: ー | E4: SA0060 | F4: 販売価格マスター | J4: 〇 | Q4: =VLOOKUP(E4,sheet1!$B$2:$D$3209,3,FALSE) -> 1222 | R4: 〇 | S4: 〇 | T4: 〇 | U4: 〇 | V4: 〇 | Z4: 〇 | AB4: 〇 | AC4: 〇 | AD4: =VLOOKUP(E4,sheet1!$B$2:$C$3209,2,FALSE) -> 販売価格マスターメンテナンス | AE4: 〇 | AF4: 02.販売価格マスター | AG4: SA0060 | AH4: =MID(AF4,4,100) -> 販売価格マスター | AO4: =TRIM(MIDB(AQ4,4,99)) -> 販売価格マスター | AP4: =TRIM(AR4) -> SA0060 | AQ4: 02.販売価格マスター | AR4: SA0060 | AS4: =TRIM(MID(AU4,4,99)) -> 販売価格マスター | AT4: =TRIM(AV4) -> SA0060 | AU4: 02.販売価格マスター | AV4: SA0060
A5: 3 | B5: 販売システム | C5: マスター保守 | D5: ー | E5: SA0120 | F5: 値引限度率マスター | J5: 〇 | Q5: =VLOOKUP(E5,sheet1!$B$2:$D$3209,3,FALSE) -> 872 | R5: 〇 | S5: 〇 | T5: 〇 | U5: 〇 | V5: 〇 | AB5: 〇 | AC5: 〇 | AD5: =VLOOKUP(E5,sheet1!$B$2:$C$3209,2,FALSE) -> 値引限度額・率マスターメンテナンス | AF5: 03.値引限度率マスター | AG5: SA0120 | AH5: =MID(AF5,4,100) -> 値引限度率マスター | AO5: =TRIM(MIDB(AQ5,4,99)) -> 値引限度率マスター | AP5: =TRIM(AR5) -> SA0120 | AQ5: 03.値引限度率マスター | AR5: SA0120 | AS5: =TRIM(MID(AU5,4,99)) -> 値引限度率マスター | AT5: =TRIM(AV5) -> SA0120 | AU5: 03.値引限度率マスター | AV5: SA0120
A6: 4 | B6: 販売システム | C6: マスター保守 | D6: ー | E6: SA0080 | F6: 修理作業費マスター | J6: 〇 | Q6: =VLOOKUP(E6,sheet1!$B$2:$D$3209,3,FALSE) -> 471 | R6: 〇 | S6: 〇 | T6: 〇 | U6: 〇 | V6: 〇 | AB6: 〇 | AC6: 〇 | AD6: =VLOOKUP(E6,sheet1!$B$2:$C$3209,2,FALSE) -> 修理作業費マスターメンテ | AF6: 04.修理作業費マスター | AG6: SA0080 | AH6: =MID(AF6,4,100) -> 修理作業費マスター | AO6: =TRIM(MIDB(AQ6,4,99)) -> 修理作業費マスター | AP6: =TRIM(AR6) -> SA0080 | AQ6: 04.修理作業費マスター | AR6: SA0080 | AS6: =TRIM(MID(AU6,4,99)) -> 修理作業費マスター | AT6: =TRIM(AV6) -> SA0080 | AU6: 04.修理作業費マスター | AV6: SA0080
A7: 5 | B7: 販売システム | C7: マスター保守 | D7: ー | E7: SA0210 | F7: 無償保証期間マスターメンテ | J7: 〇 | Q7: =VLOOKUP(E7,sheet1!$B$2:$D$3209,3,FALSE) -> 631 | R7: 〇 | S7: 〇 | T7: 〇 | U7: 〇 | V7: 〇 | AB7: 〇 | AC7: 〇 | AD7: =VLOOKUP(E7,sheet1!$B$2:$C$3209,2,FALSE) -> 無償保証期間マスターメンテ | AF7: 05.無償保証期間マスターメンテ | AG7: SA0210 | AH7: =MID(AF7,4,100) -> 無償保証期間マスターメンテ | AO7: =TRIM(MIDB(AQ7,4,99)) -> 無償保証期間マスターメンテ | AP7: =TRIM(AR7) -> SA0210 | AQ7: 05.無償保証期間マスターメンテ | AR7: SA0210 | AS7: =TRIM(MID(AU7,4,99)) -> 無償保証期間マスターメンテ | AT7: =TRIM(AV7) -> SA0210 | AU7: 05.無償保証期間マスターメンテ | AV7: SA0210
A8: 6 | B8: 販売システム | C8: マスター保守 | D8: ー | E8: MM0020 | F8: 銀行マスタメンテナンス | J8: 〇 | Q8: =VLOOKUP(E8,sheet1!$B$2:$D$3209,3,FALSE) -> 391 | R8: 〇 | S8: 〇 | T8: 〇 | U8: 〇 | V8: 〇 | AB8: 〇 | AC8: 〇 | AD8: =VLOOKUP(E8,sheet1!$B$2:$C$3209,2,FALSE) -> 銀行マスタメンテナンス | AF8: 06.銀行マスタメンテナンス | AG8: MM0020 | AH8: =MID(AF8,4,100) -> 銀行マスタメンテナンス | AO8: =TRIM(MIDB(AQ8,4,99)) -> 銀行マスタメンテナンス | AP8: =TRIM(AR8) -> MM0020 | AQ8: 06.銀行マスタメンテナンス | AR8: MM0020 | AS8: =TRIM(MID(AU8,4,99)) -> 銀行マスタメンテナンス | AT8: =TRIM(AV8) -> MM0020 | AU8: 06.銀行マスタメンテナンス | AV8: MM0020
A9: 7 | B9: 販売システム | C9: マスター保守 | D9: ー | E9: SA0220 | F9: 銀行振込口座マスター | J9: 〇 | Q9: =VLOOKUP(E9,sheet1!$B$2:$D$3209,3,FALSE) -> 535 | R9: 〇 | S9: 〇 | T9: 〇 | U9: 〇 | V9: 〇 | AB9: 〇 | AC9: 〇 | AD9: =VLOOKUP(E9,sheet1!$B$2:$C$3209,2,FALSE) -> 銀行振込口座マスターメンテ | AF9: 07.銀行振込口座マスター | AG9: SA0220 | AH9: =MID(AF9,4,100) -> 銀行振込口座マスター | AO9: =TRIM(MIDB(AQ9,4,99)) -> 銀行振込口座マスター | AP9: =TRIM(AR9) -> SA0220 | AQ9: 07.銀行振込口座マスター | AR9: SA0220 | AS9: =TRIM(MID(AU9,4,99)) -> 銀行振込口座マスター | AT9: =TRIM(AV9) -> SA0220 | AU9: 07.銀行振込口座マスター | AV9: SA0220
A10: 8 | B10: 販売システム | C10: マスター保守 | D10: 与信限度申請書管理 | E10: SA0170 | F10: 与信決裁内容登録 | J10: 〇 | Q10: =VLOOKUP(E10,sheet1!$B$2:$D$3209,3,FALSE) -> 1116 | R10: 〇 | S10: 〇 | T10: 〇 | U10: 〇 | V10: 〇 | AC10: 〇 | AD10: =VLOOKUP(E10,sheet1!$B$2:$C$3209,2,FALSE) -> 与信決裁内容登録 | AE10: 〇 | AF10: 01.与信決裁内容登録 | AG10: SA0170 | AH10: =MID(AF10,4,100) -> 与信決裁内容登録 | AO10: =TRIM(MIDB(AQ10,4,99)) -> 与信決裁内容登録 | AP10: =TRIM(AR10) -> SA0170 | AQ10: 01.与信決裁内容登録 | AR10: SA0170 | AS10: =TRIM(MID(AU10,4,99)) -> 与信決裁内容登録 | AT10: =TRIM(AV10) -> SA0170 | AU10: 01.与信決裁内容登録 | AV10: SA0170
A11: 9 | B11: 販売システム | C11: マスター保守 | D11: 与信限度申請書管理 | E11: SA2435 | F11: 月末与信残高集計 更新系 | J11: 〇 | Q11: =VLOOKUP(E11,sheet1!$B$2:$D$3209,3,FALSE) -> 210 | R11: 〇 | S11: 〇 | T11: 〇 | U11: 〇 | V11: 〇 | AC11: 〇 | AD11: =VLOOKUP(E11,sheet1!$B$2:$C$3209,2,FALSE) -> 月末与信残高集計指示画面 | AE11: 〇 | AF11: 11.月末与信残高集計 更新系 | AG11: SA2435 | AH11: =MID(AF11,4,100) -> 月末与信残高集計 更新系 | AO11: =TRIM(MIDB(AQ11,4,99)) -> 月末与信残高集計 更新系 | AP11: =TRIM(AR11) -> SA2435 | AQ11: 11.月末与信残高集計 更新系 | AR11: SA2435 | AS11: =TRIM(MID(AU11,4,99)) -> 月末与信残高集計 更新系 | AT11: =TRIM(AV11) -> SA2435 | AU11: 11.月末与信残高集計 更新系 | AV11: SA2435
A12: 10 | B12: 販売システム | C12: マスター保守 | D12: 与信限度申請書管理 | E12: SA0280 | F12: 与信再更新対象データ作成 | J12: 〇 | Q12: =VLOOKUP(E12,sheet1!$B$2:$D$3209,3,FALSE) -> 408 | R12: 〇 | S12: 〇 | T12: 〇 | U12: 〇 | V12: 〇 | AC12: 〇 | AD12: =VLOOKUP(E12,sheet1!$B$2:$C$3209,2,FALSE) -> 与信再更新対象データ作成 | AF12: 12.与信再更新対象データ作成 | AG12: SA0280 | AH12: =MID(AF12,4,100) -> 与信再更新対象データ作成 | AO12: =TRIM(MIDB(AQ12,4,99)) -> 与信再更新対象データ作成 | AP12: =TRIM(AR12) -> SA0280 | AQ12: 12.与信再更新対象データ作成 | AR12: SA0280 | AS12: =TRIM(MID(AU12,4,99)) -> 与信再更新対象データ作成 | AT12: =TRIM(AV12) -> SA0280 | AU12: 12.与信再更新対象データ作成 | AV12: SA0280
A13: 11 | B13: 販売システム | C13: マスター保守 | D13: 与信限度申請書管理 | E13: SA0180 | F13: 外部評価登録 | J13: 〇 | Q13: =VLOOKUP(E13,sheet1!$B$2:$D$3209,3,FALSE) -> 528 | R13: 〇 | S13: 〇 | T13: 〇 | U13: 〇 | V13: 〇 | AC13: 〇 | AD13: =VLOOKUP(E13,sheet1!$B$2:$C$3209,2,FALSE) -> 外部評価登録 | AF13: 13.外部評価登録 | AG13: SA0180 | AH13: =MID(AF13,4,100) -> 外部評価登録 | AO13: =TRIM(MIDB(AQ13,4,99)) -> 外部評価登録 | AP13: =TRIM(AR13) -> SA0180 | AQ13: 13.外部評価登録 | AR13: SA0180 | AS13: =TRIM(MID(AU13,4,99)) -> 外部評価登録 | AT13: =TRIM(AV13) -> SA0180 | AU13: 13.外部評価登録 | AV13: SA0180
A14: 12 | B14: 販売システム | C14: マスター保守 | D14: 与信限度申請書管理 | E14: SA2440 | F14: 与信再更新申請書印刷 | J14: 〇 | Q14: =VLOOKUP(E14,sheet1!$B$2:$D$3209,3,FALSE) -> 513 | R14: 〇 | S14: 〇 | T14: 〇 | U14: 〇 | V14: 〇 | AC14: 〇 | AD14: =VLOOKUP(E14,sheet1!$B$2:$C$3209,2,FALSE) -> 与信限度額申請客先リスト印刷 | AF14: 14.与信再更新申請書印刷 | AG14: SA2440 | AH14: =MID(AF14,4,100) -> 与信再更新申請書印刷 | AO14: =TRIM(MIDB(AQ14,4,99)) -> 与信再更新申請書印刷 | AP14: =TRIM(AR14) -> SA2440 | AQ14: 14.与信再更新申請書印刷 | AR14: SA2440 | AS14: =TRIM(MID(AU14,4,99)) -> 与信再更新申請書印刷 | AT14: =TRIM(AV14) -> SA2440 | AU14: 14.与信再更新申請書印刷 | AV14: SA2440
A15: 13 | B15: 販売システム | C15: マスター保守 | D15: 与信限度申請書管理 | E15: SA0200 | F15: 与信再更新処理 | J15: 〇 | Q15: =VLOOKUP(E15,sheet1!$B$2:$D$3209,3,FALSE) -> 819 | R15: 〇 | S15: 〇 | T15: 〇 | U15: 〇 | V15: 〇 | AC15: 〇 | AD15: =VLOOKUP(E15,sheet1!$B$2:$C$3209,2,FALSE) -> 与信再申請更新 | AF15: 15.与信再更新処理 | AG15: SA0200 | AH15: =MID(AF15,4,100) -> 与信再更新処理 | AO15: =TRIM(MIDB(AQ15,4,99)) -> 与信再更新処理 | AP15: =TRIM(AR15) -> SA0200 | AQ15: 15.与信再更新処理 | AR15: SA0200 | AS15: =TRIM(MID(AU15,4,99)) -> 与信再更新処理 | AT15: =TRIM(AV15) -> SA0200 | AU15: 15.与信再更新処理 | AV15: SA0200
A16: 14 | B16: 販売システム | C16: マスター保守 | D16: 与信限度申請書管理 | E16: SA0190 | F16: 期間限定与信限度額登録 | J16: 〇 | Q16: =VLOOKUP(E16,sheet1!$B$2:$D$3209,3,FALSE) -> 351 | R16: 〇 | S16: 〇 | T16: 〇 | U16: 〇 | V16: 〇 | AC16: 〇 | AD16: =VLOOKUP(E16,sheet1!$B$2:$C$3209,2,FALSE) -> 期間限定与信限度登録 | AF16: 21.期間限定与信限度額登録 | AG16: SA0190 | AH16: =MID(AF16,4,100) -> 期間限定与信限度額登録 | AO16: =TRIM(MIDB(AQ16,4,99)) -> 期間限定与信限度額登録 | AP16: =TRIM(AR16) -> SA0190 | AQ16: 21.期間限定与信限度額登録 | AR16: SA0190 | AS16: =TRIM(MID(AU16,4,99)) -> 期間限定与信限度額登録 | AT16: =TRIM(AV16) -> SA0190 | AU16: 21.期間限定与信限度額登録 | AV16: SA0190
A17: 15 | B17: 販売システム | C17: マスター保守 | D17: 与信限度申請書管理 | E17: SA2450 | F17: 期間限定与信登録中客先印刷 | J17: 〇 | Q17: =VLOOKUP(E17,sheet1!$B$2:$D$3209,3,FALSE) -> 327 | R17: 〇 | S17: 〇 | T17: 〇 | U17: 〇 | V17: 〇 | AC17: 〇 | AD17: =VLOOKUP(E17,sheet1!$B$2:$C$3209,2,FALSE) -> 期間限定与信限度客先印刷 | AF17: 22.期間限定与信登録中客先印刷 | AG17: SA2450 | AH17: =MID(AF17,4,100) -> 期間限定与信登録中客先印刷 | AO17: =TRIM(MIDB(AQ17,4,99)) -> 期間限定与信登録中客先印刷 | AP17: =TRIM(AR17) -> SA2450 | AQ17: 22.期間限定与信登録中客先印刷 | AR17: SA2450 | AS17: =TRIM(MID(AU17,4,99)) -> 期間限定与信登録中客先印刷 | AT17: =TRIM(AV17) -> SA2450 | AU17: 22.期間限定与信登録中客先印刷 | AV17: SA2450
A18: 16 | B18: 販売システム | C18: マスター保守 | D18: 与信限度申請書管理 | E18: SA5180 | F18: 与信申請データ照会 | J18: 〇 | Q18: =VLOOKUP(E18,sheet1!$B$2:$D$3209,3,FALSE) -> 576 | R18: 〇 | S18: 〇 | T18: 〇 | U18: 〇 | V18: 〇 | AC18: 〇 | AD18: =VLOOKUP(E18,sheet1!$B$2:$C$3209,2,FALSE) -> 与信決裁内容照会 | AF18: 51.与信申請データ照会 | AG18: SA5180 | AH18: =MID(AF18,4,100) -> 与信申請データ照会 | AO18: =TRIM(MIDB(AQ18,4,99)) -> 与信申請データ照会 | AP18: =TRIM(AR18) -> SA5180 | AQ18: 51.与信申請データ照会 | AR18: SA5180 | AS18: =TRIM(MID(AU18,4,99)) -> 与信申請データ照会 | AT18: =TRIM(AV18) -> SA5180 | AU18: 51.与信申請データ照会 | AV18: SA5180
A19: 17 | B19: 販売システム | C19: マスター保守 | D19: 与信限度申請書管理 | E19: Query | F19: 与信再更新申請書データ抽出 | K19: 〇 | N19: 〇 | Q19: =VLOOKUP(E19,sheet1!$B$2:$D$3209,3,FALSE) -> #N/A | R19: 〇 | S19: 〇 | T19: 〇 | U19: 〇 | V19: 〇 | AC19: 〇 | AD19: =VLOOKUP(E19,sheet1!$B$2:$C$3209,2,FALSE) -> #N/A | AF19: 61.与信再更新申請書データ抽出 | AG19: Query | AH19: =MID(AF19,4,100) -> 与信再更新申請書データ抽出 | AO19: =TRIM(MIDB(AQ19,4,99)) -> 与信再更新申請書データ抽出 | AP19: =TRIM(AR19) -> Query | AQ19: 61.与信再更新申請書データ抽出 | AR19: Query | AS19: =TRIM(MID(AU19,4,99)) -> 与信再更新申請書データ抽出 | AT19: =TRIM(AV19) -> Query | AU19: 61.与信再更新申請書データ抽出 | AV19: Query
A20: 18 | B20: 販売システム | C20: マスター保守 | D20: 与信限度申請書管理 | E20: Query | F20: 与信決裁内容ＤＬ 日付指定JCM | K20: 〇 | N20: 〇 | Q20: =VLOOKUP(E20,sheet1!$B$2:$D$3209,3,FALSE) -> #N/A | R20: 〇 | S20: 〇 | T20: 〇 | U20: 〇 | V20: 〇 | AC20: 〇 | AD20: =VLOOKUP(E20,sheet1!$B$2:$C$3209,2,FALSE) -> #N/A | AF20: 62 与信決裁内容ＤＬ 日付指定JCM | AG20: Query | AH20: =MID(AF20,4,100) -> 与信決裁内容ＤＬ 日付指定JCM | AO20: =TRIM(MIDB(AQ20,4,99)) -> 与信決裁内容ＤＬ 日付指定JCM | AP20: =TRIM(AR20) -> Query | AQ20: 62 与信決裁内容ＤＬ 日付指定JCM | AR20: Query | AS20: =TRIM(MID(AU20,4,99)) -> 与信決裁内容ＤＬ 日付指定JCM | AT20: =TRIM(AV20) -> Query | AU20: 62 与信決裁内容ＤＬ 日付指定JCM | AV20: Query
A21: 19 | B21: 販売システム | C21: マスター保守 | D21: 与信限度申請書管理 | E21: Query | F21: 与信決裁内容ＤＬ 日付指定JS | K21: 〇 | N21: 〇 | Q21: =VLOOKUP(E21,sheet1!$B$2:$D$3209,3,FALSE) -> #N/A | R21: 〇 | S21: 〇 | T21: 〇 | U21: 〇 | V21: 〇 | AC21: 〇 | AD21: =VLOOKUP(E21,sheet1!$B$2:$C$3209,2,FALSE) -> #N/A | AF21: 63 与信決裁内容ＤＬ 日付指定JS | AG21: Query | AH21: =MID(AF21,4,100) -> 与信決裁内容ＤＬ 日付指定JS | AO21: =TRIM(MIDB(AQ21,4,99)) -> 与信決裁内容ＤＬ 日付指定JS | AP21: =TRIM(AR21) -> Query | AQ21: 63 与信決裁内容ＤＬ 日付指定JS | AR21: Query | AS21: =TRIM(MID(AU21,4,99)) -> 与信決裁内容ＤＬ 日付指定JS | AT21: =TRIM(AV21) -> Query | AU21: 63 与信決裁内容ＤＬ 日付指定JS | AV21: Query
A22: 20 | B22: 販売システム | C22: マスター保守 | D22: ー | E22: PD0132 | F22: 得意先マスタ保守 | J22: 〇 | Q22: =VLOOKUP(E22,sheet1!$B$2:$D$3209,3,FALSE) -> 1485 | R22: 〇 | S22: 〇 | T22: 〇 | U22: 〇 | V22: 〇 | AC22: 〇 | AD22: =VLOOKUP(E22,sheet1!$B$2:$C$3209,2,FALSE) -> 得意先マスターメンテナンス | AF22: 11.得意先マスタ保守 | AG22: PD0132 | AH22: =MID(AF22,4,100) -> 得意先マスタ保守 | AO22: =TRIM(MIDB(AQ22,4,99)) -> 得意先マスタ保守 | AP22: =TRIM(AR22) -> PD0132 | AQ22: 11.得意先マスタ保守 | AR22: PD0132 | AS22: =TRIM(MID(AU22,4,99)) -> 得意先マスタ保守 | AT22: =TRIM(AV22) -> PD0132 | AU22: 11.得意先マスタ保守 | AV22: PD0132
A23: 21 | B23: 販売システム | C23: マスター保守 | D23: ー | E23: SA0070 | F23: 品目・販売課関連ﾏｽﾀｰ | J23: 〇 | Q23: =VLOOKUP(E23,sheet1!$B$2:$D$3209,3,FALSE) -> 688 | R23: 〇 | T23: 〇 | V23: 〇 | AB23: 〇 | AC23: 〇 | AD23: =VLOOKUP(E23,sheet1!$B$2:$C$3209,2,FALSE) -> 品目・販売課関連マスターメンテナンス | AF23: 21.品目・販売課関連ﾏｽﾀｰ | AG23: SA0070 | AH23: =MID(AF23,4,100) -> 品目・販売課関連ﾏｽﾀｰ | AO23: =TRIM(MIDB(AQ23,4,99)) | AP23: =TRIM(AR23) | AS23: =TRIM(MID(AU23,4,99)) | AT23: =TRIM(AV23)
A24: 22 | B24: 販売システム | C24: マスター保守 | D24: ー | E24: SA0090 | F24: ｼﾘｱﾙ NO付加情報ﾏｽﾀｰ | J24: 〇 | Q24: =VLOOKUP(E24,sheet1!$B$2:$D$3209,3,FALSE) -> 673 | R24: 〇 | T24: 〇 | V24: 〇 | AB24: 〇 | AC24: 〇 | AD24: =VLOOKUP(E24,sheet1!$B$2:$C$3209,2,FALSE) -> シリアルＮＯ付加情報マスターメンテナンス | AF24: 22.ｼﾘｱﾙ NO付加情報ﾏｽﾀｰ | AG24: SA0090 | AH24: =MID(AF24,4,100) -> ｼﾘｱﾙ NO付加情報ﾏｽﾀｰ | AO24: =TRIM(MIDB(AQ24,4,99)) | AP24: =TRIM(AR24) | AS24: =TRIM(MID(AU24,4,99)) | AT24: =TRIM(AV24)
A25: 23 | B25: 販売システム | C25: マスター保守 | D25: ー | E25: SA0110 | F25: 荷姿マスター | J25: 〇 | Q25: =VLOOKUP(E25,sheet1!$B$2:$D$3209,3,FALSE) -> 666 | R25: 〇 | T25: 〇 | V25: 〇 | AB25: 〇 | AC25: 〇 | AD25: =VLOOKUP(E25,sheet1!$B$2:$C$3209,2,FALSE) -> 荷姿マスターメンテナンス | AF25: 23.荷姿マスター | AG25: SA0110 | AH25: =MID(AF25,4,100) -> 荷姿マスター | AO25: =TRIM(MIDB(AQ25,4,99)) | AP25: =TRIM(AR25) | AS25: =TRIM(MID(AU25,4,99)) | AT25: =TRIM(AV25)
A26: 24 | B26: 販売システム | C26: マスター保守 | D26: ー | E26: SA0140 | F26: 自動引当可能課マスター | J26: 〇 | Q26: =VLOOKUP(E26,sheet1!$B$2:$D$3209,3,FALSE) -> 613 | R26: 〇 | T26: 〇 | V26: 〇 | AB26: 〇 | AC26: 〇 | AD26: =VLOOKUP(E26,sheet1!$B$2:$C$3209,2,FALSE) -> 自動引当可能課マスターメンテナンス | AF26: 24.自動引当可能課マスター | AG26: SA0140 | AH26: =MID(AF26,4,100) -> 自動引当可能課マスター | AO26: =TRIM(MIDB(AQ26,4,99)) | AP26: =TRIM(AR26) | AS26: =TRIM(MID(AU26,4,99)) | AT26: =TRIM(AV26)
A27: 25 | B27: 販売システム | C27: マスター保守 | D27: ー | E27: SA0010 | F27: 不具合内容マスター | J27: 〇 | Q27: =VLOOKUP(E27,sheet1!$B$2:$D$3209,3,FALSE) -> 243 | R27: 〇 | S27: 〇 | T27: 〇 | U27: 〇 | V27: 〇 | AB27: 〇 | AC27: 〇 | AD27: =VLOOKUP(E27,sheet1!$B$2:$C$3209,2,FALSE) -> 不具合内容マスターメンテ | AF27: 51.不具合内容マスター | AG27: SA0010 | AH27: =MID(AF27,4,100) -> 不具合内容マスター | AO27: =TRIM(MIDB(AQ27,4,99)) -> 不具合内容マスター | AP27: =TRIM(AR27) -> SA0010 | AQ27: 51.不具合内容マスター | AR27: SA0010 | AS27: =TRIM(MID(AU27,4,99)) -> 不具合内容マスター | AT27: =TRIM(AV27) -> SA0010 | AU27: 51.不具合内容マスター | AV27: SA0010
A28: 26 | B28: 販売システム | C28: マスター保守 | D28: ー | E28: SA0020 | F28: 不具合原因マスター | J28: 〇 | Q28: =VLOOKUP(E28,sheet1!$B$2:$D$3209,3,FALSE) -> 242 | R28: 〇 | S28: 〇 | T28: 〇 | U28: 〇 | V28: 〇 | AB28: 〇 | AC28: 〇 | AD28: =VLOOKUP(E28,sheet1!$B$2:$C$3209,2,FALSE) -> 不具合原因マスターメンテ | AF28: 52.不具合原因マスター | AG28: SA0020 | AH28: =MID(AF28,4,100) -> 不具合原因マスター | AO28: =TRIM(MIDB(AQ28,4,99)) -> 不具合原因マスター | AP28: =TRIM(AR28) -> SA0020 | AQ28: 52.不具合原因マスター | AR28: SA0020 | AS28: =TRIM(MID(AU28,4,99)) -> 不具合原因マスター | AT28: =TRIM(AV28) -> SA0020 | AU28: 52.不具合原因マスター | AV28: SA0020
A29: 27 | B29: 販売システム | C29: マスター保守 | D29: ー | E29: SA0030 | F29: 処置内容マスター | J29: 〇 | Q29: =VLOOKUP(E29,sheet1!$B$2:$D$3209,3,FALSE) -> 243 | R29: 〇 | S29: 〇 | T29: 〇 | U29: 〇 | V29: 〇 | AB29: 〇 | AC29: 〇 | AD29: =VLOOKUP(E29,sheet1!$B$2:$C$3209,2,FALSE) -> 処置内容マスターメンテ | AF29: 53.処置内容マスター | AG29: SA0030 | AH29: =MID(AF29,4,100) -> 処置内容マスター | AO29: =TRIM(MIDB(AQ29,4,99)) -> 処置内容マスター | AP29: =TRIM(AR29) -> SA0030 | AQ29: 53.処置内容マスター | AR29: SA0030 | AS29: =TRIM(MID(AU29,4,99)) -> 処置内容マスター | AT29: =TRIM(AV29) -> SA0030 | AU29: 53.処置内容マスター | AV29: SA0030
A30: 28 | B30: 販売システム | C30: マスター保守 | D30: ー | E30: SA0100 | F30: 保守契約マスター | J30: 〇 | Q30: =VLOOKUP(E30,sheet1!$B$2:$D$3209,3,FALSE) -> 1867 | R30: 〇 | S30: 〇 | T30: 〇 | U30: 〇 | V30: 〇 | AB30: 〇 | AC30: 〇 | AD30: =VLOOKUP(E30,sheet1!$B$2:$C$3209,2,FALSE) -> 保守契約マスターメンテ | AF30: 54.保守契約マスター | AG30: SA0100 | AH30: =MID(AF30,4,100) -> 保守契約マスター | AO30: =TRIM(MIDB(AQ30,4,99)) -> 保守契約マスター | AP30: =TRIM(AR30) -> SA0030 | AQ30: 54.保守契約マスター | AR30: SA0030 | AS30: =TRIM(MID(AU30,4,99)) -> 保守契約マスター | AT30: =TRIM(AV30) -> SA0030 | AU30: 54.保守契約マスター | AV30: SA0030
A31: 29 | B31: 販売システム | C31: マスター保守 | D31: ー | E31: AC0032 | F31: ｼｽﾃﾑ式・単能式品目F | J31: 〇 | Q31: =VLOOKUP(E31,sheet1!$B$2:$D$3209,3,FALSE) -> 563 | R31: 〇 | S31: 〇 | T31: 〇 | U31: 〇 | V31: 〇 | Z31: 〇 | AB31: 〇 | AC31: 〇 | AD31: =VLOOKUP(E31,sheet1!$B$2:$C$3209,2,FALSE) -> ｼｽﾃﾑ式・単能式品目ﾌｧｲﾙﾒﾝﾃﾅﾝｽ | AF31: 61.ｼｽﾃﾑ式・単能式品目F | AG31: AC0032 | AH31: =MID(AF31,4,100) -> ｼｽﾃﾑ式・単能式品目F | AO31: =TRIM(MIDB(AQ31,4,99)) -> ｼｽﾃﾑ式・単能式品目F | AP31: =TRIM(AR31) -> AC0032 | AQ31: 61. ｼｽﾃﾑ式・単能式品目F | AR31: AC0032 | AS31: =TRIM(MID(AU31,4,99)) -> ｼｽﾃﾑ式・単能式品目F | AT31: =TRIM(AV31) -> AC0032 | AU31: 61. ｼｽﾃﾑ式・単能式品目F | AV31: AC0032
A32: 30 | B32: 販売システム | C32: マスター照会 | D32: ー | E32: SA1540 | F32: 与信マスター・親得意 | J32: 〇 | Q32: =VLOOKUP(E32,sheet1!$B$2:$D$3209,3,FALSE) -> 387 | R32: 〇 | S32: 〇 | T32: 〇 | U32: 〇 | V32: 〇 | Z32: 〇 | AB32: 〇 | AC32: 〇 | AD32: =VLOOKUP(E32,sheet1!$B$2:$C$3209,2,FALSE) -> 与信マスター照会（１） | AF32: 01.与信マスター・親得意 | AG32: SA1540 | AH32: =MID(AF32,4,100) -> 与信マスター・親得意 | AL32: =TRIM(AN32) -> 与信マスター・親得意 | AM32: 〇 | AN32: 与信マスター・親得意 | AO32: =TRIM(MIDB(AQ32,4,99)) -> 与信マスター・親得意 | AP32: =TRIM(AR32) -> SA1540 | AQ32: 01.与信マスター・親得意 | AR32: SA1540 | AS32: =TRIM(MID(AU32,4,99)) -> 与信マスター・親得意 | AT32: =TRIM(AV32) -> SA1540 | AU32: 01.与信マスター・親得意 | AV32: SA1540
A33: 31 | B33: 販売システム | C33: マスター照会 | D33: ー | E33: SA1550 | F33: 与信マスター・得意先 | J33: 〇 | Q33: =VLOOKUP(E33,sheet1!$B$2:$D$3209,3,FALSE) -> 429 | R33: 〇 | S33: 〇 | T33: 〇 | U33: 〇 | V33: 〇 | Z33: 〇 | AB33: 〇 | AC33: 〇 | AD33: =VLOOKUP(E33,sheet1!$B$2:$C$3209,2,FALSE) -> 与信マスター照会（２） | AF33: 02.与信マスター・得意先 | AG33: SA1550 | AH33: =MID(AF33,4,100) -> 与信マスター・得意先 | AL33: =TRIM(AN33) -> 与信マスター・得意先 | AM33: 〇 | AN33: 与信マスター・得意先 | AO33: =TRIM(MIDB(AQ33,4,99)) -> 与信マスター・得意先 | AP33: =TRIM(AR33) -> SA1550 | AQ33: 02.与信マスター・得意先 | AR33: SA1550 | AS33: =TRIM(MID(AU33,4,99)) -> 与信マスター・得意先 | AT33: =TRIM(AV33) -> SA1550 | AU33: 02.与信マスター・得意先 | AV33: SA1550
A34: 32 | B34: 販売システム | C34: マスター照会 | D34: ー | E34: SA1570 | F34: 販売価格マスター | J34: 〇 | Q34: =VLOOKUP(E34,sheet1!$B$2:$D$3209,3,FALSE) -> 500 | R34: 〇 | S34: 〇 | T34: 〇 | U34: 〇 | V34: 〇 | Z34: 〇 | AB34: 〇 | AC34: 〇 | AD34: =VLOOKUP(E34,sheet1!$B$2:$C$3209,2,FALSE) -> 販売価格マスター照会 | AF34: 03.販売価格マスター | AG34: SA1570 | AH34: =MID(AF34,4,100) -> 販売価格マスター | AL34: =TRIM(AN34) -> 販売価格マスター | AM34: 〇 | AN34: 販売価格マスター | AO34: =TRIM(MIDB(AQ34,4,99)) -> 販売価格マスター | AP34: =TRIM(AR34) -> SA1570 | AQ34: 03.販売価格マスター | AR34: SA1570 | AS34: =TRIM(MID(AU34,4,99)) -> 販売価格マスター | AT34: =TRIM(AV34) -> SA1570 | AU34: 03.販売価格マスター | AV34: SA1570
A35: 33 | B35: 販売システム | C35: マスター照会 | D35: ー | E35: SA1630 | F35: 値引限度率マスター | J35: 〇 | Q35: =VLOOKUP(E35,sheet1!$B$2:$D$3209,3,FALSE) -> 340 | R35: 〇 | S35: 〇 | T35: 〇 | U35: 〇 | V35: 〇 | Z35: 〇 | AB35: 〇 | AC35: 〇 | AD35: =VLOOKUP(E35,sheet1!$B$2:$C$3209,2,FALSE) -> 値引限度額・率マスター照会 | AF35: 04.値引限度率マスター | AG35: SA1630 | AH35: =MID(AF35,4,100) -> 値引限度率マスター | AL35: =TRIM(AN35) -> 値引限度率マスター | AM35: 〇 | AN35: 値引限度率マスター | AO35: =TRIM(MIDB(AQ35,4,99)) -> 値引限度率マスター | AP35: =TRIM(AR35) -> SA1630 | AQ35: 04.値引限度率マスター | AR35: SA1630 | AS35: =TRIM(MID(AU35,4,99)) -> 値引限度率マスター | AT35: =TRIM(AV35) -> SA1630 | AU35: 04.値引限度率マスター | AV35: SA1630
A36: 34 | B36: 販売システム | C36: マスター照会 | D36: ー | E36: SA1590 | F36: 修理作業費マスター | J36: 〇 | Q36: =VLOOKUP(E36,sheet1!$B$2:$D$3209,3,FALSE) -> 281 | R36: 〇 | S36: 〇 | T36: 〇 | U36: 〇 | V36: 〇 | Z36: 〇 | AB36: 〇 | AC36: 〇 | AD36: =VLOOKUP(E36,sheet1!$B$2:$C$3209,2,FALSE) -> 修理作業費マスター照会 | AF36: 05.修理作業費マスター | AG36: SA1590 | AH36: =MID(AF36,4,100) -> 修理作業費マスター | AL36: =TRIM(AN36) -> 修理作業費マスター | AM36: 〇 | AN36: 修理作業費マスター | AO36: =TRIM(MIDB(AQ36,4,99)) -> 修理作業費マスター | AP36: =TRIM(AR36) -> SA1590 | AQ36: 05.修理作業費マスター | AR36: SA1590 | AS36: =TRIM(MID(AU36,4,99)) -> 修理作業費マスター | AT36: =TRIM(AV36) -> SA1590 | AU36: 05.修理作業費マスター | AV36: SA1590
A37: 35 | B37: 販売システム | C37: マスター照会 | D37: ー | E37: SA1660 | F37: 販売引当優先順位Ｍ | J37: 〇 | Q37: =VLOOKUP(E37,sheet1!$B$2:$D$3209,3,FALSE) -> 353 | R37: 〇 | S37: 〇 | T37: 〇 | U37: 〇 | V37: 〇 | Z37: 〇 | AB37: 〇 | AC37: 〇 | AD37: =VLOOKUP(E37,sheet1!$B$2:$C$3209,2,FALSE) -> 販売引当優先順位マスター照会 | AF37: 06.販売引当優先順位Ｍ | AG37: SA1660 | AH37: =MID(AF37,4,100) -> 販売引当優先順位Ｍ | AL37: =TRIM(AN37) -> 販売引当優先順位Ｍ | AM37: 〇 | AN37: 販売引当優先順位Ｍ | AO37: =TRIM(MIDB(AQ37,4,99)) -> 販売引当優先順位Ｍ | AP37: =TRIM(AR37) -> SA1660 | AQ37: 06.販売引当優先順位Ｍ | AR37: SA1660 | AS37: =TRIM(MID(AU37,4,99)) -> 販売引当優先順位Ｍ | AT37: =TRIM(AV37) -> SA1660 | AU37: 06.販売引当優先順位Ｍ | AV37: SA1660
A38: 36 | B38: 販売システム | C38: マスター照会 | D38: ー | E38: SA1650 | F38: 自動引当可能課マスター | J38: 〇 | Q38: =VLOOKUP(E38,sheet1!$B$2:$D$3209,3,FALSE) -> 352 | R38: 〇 | S38: 〇 | T38: 〇 | U38: 〇 | V38: 〇 | Z38: 〇 | AB38: 〇 | AC38: 〇 | AD38: =VLOOKUP(E38,sheet1!$B$2:$C$3209,2,FALSE) -> 自動引当可能課マスター照会 | AF38: 07.自動引当可能課マスター | AG38: SA1650 | AH38: =MID(AF38,4,100) -> 自動引当可能課マスター | AL38: =TRIM(AN38) -> 自動引当可能課マスター | AM38: 〇 | AN38: 自動引当可能課マスター | AO38: =TRIM(MIDB(AQ38,4,99)) -> 自動引当可能課マスター | AP38: =TRIM(AR38) -> SA1650 | AQ38: 07.自動引当可能課マスター | AR38: SA1650 | AS38: =TRIM(MID(AU38,4,99)) -> 自動引当可能課マスター | AT38: =TRIM(AV38) -> SA1650 | AU38: 07.自動引当可能課マスター | AV38: SA1650
A39: 37 | B39: 販売システム | C39: マスター照会 | D39: ー | E39: SA1640 | F39: 発送先固有情報マスター | J39: 〇 | Q39: =VLOOKUP(E39,sheet1!$B$2:$D$3209,3,FALSE) -> 308 | R39: 〇 | S39: 〇 | T39: 〇 | U39: 〇 | V39: 〇 | Z39: 〇 | AB39: 〇 | AC39: 〇 | AD39: =VLOOKUP(E39,sheet1!$B$2:$C$3209,2,FALSE) -> 発送先固有情報マスター照会 | AF39: 08.発送先固有情報マスター | AG39: SA1640 | AH39: =MID(AF39,4,100) -> 発送先固有情報マスター | AL39: =TRIM(AN39) -> 発送先固有情報マスター | AM39: 〇 | AN39: 発送先固有情報マスター | AO39: =TRIM(MIDB(AQ39,4,99)) -> 発送先固有情報マスター | AP39: =TRIM(AR39) -> SA1640 | AQ39: 08.発送先固有情報マスター | AR39: SA1640 | AS39: =TRIM(MID(AU39,4,99)) -> 発送先固有情報マスター | AT39: =TRIM(AV39) -> SA1640 | AU39: 08.発送先固有情報マスター | AV39: SA1640
A40: 38 | B40: 販売システム | C40: マスター照会 | D40: ー | E40: SA1620 | F40: 荷姿マスター | J40: 〇 | Q40: =VLOOKUP(E40,sheet1!$B$2:$D$3209,3,FALSE) -> 284 | R40: 〇 | S40: 〇 | T40: 〇 | U40: 〇 | V40: 〇 | Z40: 〇 | AB40: 〇 | AC40: 〇 | AD40: =VLOOKUP(E40,sheet1!$B$2:$C$3209,2,FALSE) -> 荷姿マスター照会 | AF40: 09.荷姿マスター | AG40: SA1620 | AH40: =MID(AF40,4,100) -> 荷姿マスター | AL40: =TRIM(AN40) -> 荷姿マスター | AM40: 〇 | AN40: 荷姿マスター | AO40: =TRIM(MIDB(AQ40,4,99)) -> 荷姿マスター | AP40: =TRIM(AR40) -> SA1620 | AQ40: 09.荷姿マスター | AR40: SA1620 | AS40: =TRIM(MID(AU40,4,99)) -> 荷姿マスター | AT40: =TRIM(AV40) -> SA1620 | AU40: 09.荷姿マスター | AV40: SA1620
...

Sheet sheet1
A1: 属性 | B1: オブジェクト | C1: テキスト記述 | D1: ステップ数 | E1: 頭２文字 | F1: 使用日数 | H1: 確認 | I1: =SUM(H2:H3209) -> 920 | J1: =I1/3209 -> 0.28669367 | K1: =I1/L1 -> 0.45725646 | L1: =COUNTIF(A2:A3209,"RPG") -> 2012
A2: CLP | B2: #ASPOVRC | C2: ASPしきい値オーバー時KISOサブシステム強制終了 | D2: 28 | E2: #A | F2: 2 | H2: =COUNTIF('(参考)現行システム機能階層一覧'!$E$3:$E$1048576,sheet1!B2) -> 0
A3: CLP | B3: #CHGUSR01 | C3: CHGUSRPRF ALL DISABLED (JCM JCM001 JTS MEIHO GOLD) | D3: 22 | E3: #C | F3: 4 | H3: =COUNTIF('(参考)現行システム機能階層一覧'!$E$3:$E$1048576,sheet1!B3) -> 0
A4: CLP | B4: #CHGUSR02 | C4: CHGUSRPRF ALL ENABLED (JCM JCM001 JTS MEIHO GOLD) | D4: 22 | E4: #C | F4: 4 | H4: =COUNTIF('(参考)現行システム機能階層一覧'!$E$3:$E$1048576,sheet1!B4) -> 0
A5: CLP | B5: #CRTFTP | C5: ＦＴＰデータ転送 | D5: 75 | E5: #C | F5: 48 | H5: =COUNTIF('(参考)現行システム機能階層一覧'!$E$3:$E$1048576,sheet1!B5) -> 0
A6: CLP | B6: #CRTFTP2 | C6: ＦＴＰデータ転送PC >> AS(PUT) | D6: 122 | E6: #C | F6: 258 | H6: =COUNTIF('(参考)現行システム機能階層一覧'!$E$3:$E$1048576,sheet1!B6) -> 0
A7: CLP | B7: #CRTFTP3 | C7: ＦＴＰデータ転送 メイホウ納品確認書出力用 | D7: 85 | E7: #C | F7: 111 | H7: =COUNTIF('(参考)現行システム機能階層一覧'!$E$3:$E$1048576,sheet1!B7) -> 0
A8: CLP | B8: #CRTTTO | C8: ＰＣＯＭデータ転送 ダウンロード用P31954 | D8: 149 | E8: #C | F8: 982 | H8: =COUNTIF('(参考)現行システム機能階層一覧'!$E$3:$E$1048576,sheet1!B8) -> 0
A9: CLP | B9: #CRTTTO_OR | C9: ＰＣＯＭデータ転送 ダウンロード用P31954 | D9: 142 | E9: #C | F9: 1 | H9: =COUNTIF('(参考)現行システム機能階層一覧'!$E$3:$E$1048576,sheet1!B9) -> 0
A10: CLP | B10: #DSPTAP | C10: DSPTAP ' | D10: 9 | E10: #D | F10: 1 | H10: =COUNTIF('(参考)現行システム機能階層一覧'!$E$3:$E$1048576,sheet1!B10) -> 0
A11: CLP | B11: #ENDZEND | C11: ZENDPHP7サブシステム終了 | D11: 14 | E11: #E | F11: 1682 | H11: =COUNTIF('(参考)現行システム機能階層一覧'!$E$3:$E$1048576,sheet1!B11) -> 0
A12: CLP | B12: #G7MMSP | C12: ＱＲＹ 開示区分ﾏｽﾀｰ一覧表 | D12: 36 | E12: #G | F12: 108 | H12: =COUNTIF('(参考)現行システム機能階層一覧'!$E$3:$E$1048576,sheet1!B12) -> 2
A13: CLP | B13: #G8MMSP | C13: ＱＲＹ 分類ｺｰﾄﾞﾏｽﾀｰ一覧表 | D13: 15 | E13: #G | F13: 443 | H13: =COUNTIF('(参考)現行システム機能階層一覧'!$E$3:$E$1048576,sheet1!B13) -> 1
... A3209: CLP | B3209: ZPD000C | C3209: 注残分関連製番情報 抽出 | D3209: 82 | E3209: ZP | F3209: 45 | H3209: =COUNTIF('(参考)現行システム機能階層一覧'!$E$3:$E$1048576,sheet1!B3209) -> 0
C3210: =TRIM(B3210)
